<mujoco model="quadrotor0">
	<compiler inertiafromgeom="true" coordinate="local"/>
	<option	timestep="0.001" gravity="0 0 -9.81" wind="0. 0. 0." density="1.225" viscosity="1.86e-5" />
	<!-- <option	timestep="0.001" gravity="0 0 -9.81" density="1.225" viscosity="1.86e-5" /> -->
  <asset>
		<mesh file="body.stl" scale="0.0006 0.0006 0.0006"/>
		<mesh file="prop_cw.stl" scale="0.0006 0.0006 0.0006"/>
		<mesh file="prop_ccw.stl" scale="0.0006 0.0006 0.0006"/>
    <texture builtin="gradient" height="100" rgb1="1 1 1" rgb2="0 0 0" type="skybox" width="100"/>
    <texture builtin="flat" height="1278" mark="cross" markrgb="1 1 1" name="texgeom" random="0.01" rgb1="0.8 0.6 0.4" rgb2="0.8 0.6 0.4" type="cube" width="127"/>
    <texture builtin="checker" height="100" name="texplane" rgb1="0 0 0" rgb2="0.8 0.8 0.8" type="2d" width="100"/>
    <material name="MatPlane" reflectance="0.5" shininess="1" specular="1" texrepeat="60 60" texture="texplane"/>
    <material name="geom" texture="texgeom" texuniform="true"/>
  </asset>
	<worldbody>
    <light cutoff="100" diffuse="1 1 1" dir="-0 0 -1.3" directional="true" exponent="1" pos="0 0 1.3" specular=".1 .1 .1"/>
    <geom conaffinity="1" condim="3" material="MatPlane" name="floor" pos="0 0 0" rgba="0.8 0.9 0.8 1" size="40 40 40" type="plane"/>

		<body name="quadrotor" pos="0 0 0" quat="1. 0. 0. 0.">
			<geom name="core" type="mesh" mesh="body"  rgba="0.3 0.3 0.8 1" mass="0.5"/>
			<!-- <geom name="core" type="box" pos="0 0 0" quat="0. 0. 0. 1." size="0.06 0.035 0.025"  rgba="0.3 0.3 0.8 1" mass="0.1"/>
			<geom name="leg0" type="box" pos="0.05 0.05 -0.05" quat="0. -0.16 -0.16 0.97" size="0.005 0.005 0.05"  rgba="0.3 0.3 0.8 1" mass=".025"/>
			<geom name="leg1" type="box" pos="0.05 -0.05 -0.05" quat="0. -0.16 0.16 0.97" size="0.005 0.005 0.05"  rgba="0.3 0.3 0.8 1" mass=".025"/>
			<geom name="leg2" type="box" pos="-0.05 -0.05 -0.05" quat="0. 0.16 0.16 0.97" size="0.005 0.005 0.05"  rgba="0.3 0.3 0.8 1" mass=".025"/>
			<geom name="leg3" type="box" pos="-0.05 0.05 -0.05" quat="0. 0.16 -0.16 0.97" size="0.005 0.005 0.05"  rgba="0.3 0.3 0.8 1" mass=".025"/>

			<geom name="a00" type="box" pos=".071 0.071 0.0" size="0.05 0.01 0.0025"  quat=".924 0.0 0.0 0.383" rgba="0.3 0.3 0.8 1" mass=".025"/>
			<geom name="a10" type="box" pos=".071 -0.071 0.0" size="0.05 0.01 0.0025"  quat=".383 0.0 0.0 0.924" rgba="0.3 0.3 0.8 1" mass=".025"/>
			<geom name="a20" type="box" pos="-0.071 -0.071 0.0" size="0.05 0.01 0.0025"  quat="-.383 0.0 0.0 0.924" rgba="0.3 0.3 0.8 1" mass=".025"/>
			<geom name="a30" type="box" pos="-.071 0.071 0.0" size="0.05 0.01 0.0025"  quat=".924 0.0 0.0 -0.383" rgba="0.3 0.3 0.8 1" mass=".025"/> -->

			<joint name="root"   type="free" damping="0" armature="0" pos="0 0 0"/>

			<body name="leaf0" pos="0.114 0.114 0.038" >
				<joint name="leaf0-joint" type="hinge" axis="0 0 1" pos="0 0 0" armature="0"/>
				<geom name="leaf0-geo" type="mesh" mesh="prop_cw" quat="1.0 0.0 0.0 0." mass=".0025"/>
			</body>
			<body name="leaf1" pos="0.114 -0.114  0.038" >
				<joint name="leaf1-joint" type="hinge" axis="0 0 1" pos="0 0 0" armature="0"/>
				<geom name="leaf1-geo" type="mesh" mesh="prop_ccw" quat="1.0 0.0 0.0 0." mass=".0025"/>
			</body>

			<body name="leaf2" pos="-0.114 -0.114  0.038" >
				<joint name="leaf2-joint" type="hinge" axis="0 0 1" pos="0 0 0" armature="0"/>
				<geom name="leaf2-geo" type="mesh" mesh="prop_cw" quat="1.0 0.0 0.0 0." mass=".0025"/>
			</body>

			<body name="leaf3" pos="-0.114 0.114  0.038" >
				<joint name="leaf3-joint" type="hinge" axis="0 0 1" pos="0 0 0" armature="0"/>
				<geom name="leaf3-geo" type="mesh" mesh="prop_ccw" quat="1.0 0.0 0.0 0." mass=".0025"/>
			</body>
			<!-- Motor sites to attach motor actuators --->
        <site name="motor0" type="cylinder" pos=" 0.114  0.114 0.04"  size="0.05 0.0025"  quat="1.0 0.0 0.0 0." rgba="0.3 0.8 0.3 0"/>
        <site name="motor1" type="cylinder" pos=" 0.114 -0.114 0.04"  size="0.05 0.0025"  quat="1.0 0.0 0.0 0." rgba="0.3 0.8 0.3 0"/>
        <site name="motor2" type="cylinder" pos="-0.114 -0.114 0.04"  size="0.05 0.0025"  quat="1.0 0.0 0.0 0." rgba="0.3 0.8 0.3 0"/>
        <site name="motor3" type="cylinder" pos="-0.114  0.114 0.04"  size="0.05 0.0025"  quat="1.0 0.0 0.0 0." rgba="0.3 0.8 0.3 0"/>

			<!-- Thruster geometries for collisions since site's are excluded from collision checking --->
        <!-- <geom name="thruster0" type="cylinder" pos=" 0.1  0.1  0.01" size="0.05 0.0025"  quat = "1.0 0.0 0.0 0." rgba="0.3 0.8 0.3 1" mass = ".025"/>
        <geom name="thruster1" type="cylinder" pos=" 0.1 -0.1  0.01" size="0.05 0.0025"  quat = "1.0 0.0 0.0 0." rgba="0.3 0.8 0.3 1" mass = ".025"/>
        <geom name="thruster2" type="cylinder" pos="-0.1 -0.1  0.01" size="0.05 0.0025"  quat = "1.0 0.0 0.0 0." rgba="0.3 0.8 0.3 1" mass = ".025"/>
        <geom name="thruster3" type="cylinder" pos="-0.1  0.1  0.01" size="0.05 0.0025"  quat = "1.0 0.0 0.0 0." rgba="0.3 0.8 0.3 1" mass = ".025"/> -->

		</body>


		<!-- <body name="leaf" pos="0 -2 1">
			<geom name="core2" type="box" pos="0 0 0" quat="0. 0. 0. 1." size="0.06 0.035 0.025"  rgba="0.3 0.3 0.8 1" mass=".1"/>

			<joint name="leaf0-joint" type="free" damping="0" armature="0"/>
			<geom name="leaf0-geo" type="mesh" mesh="prop_ccw" pos="0.1 0.1 0.025" quat="1.0 0.0 0.0 0." mass=".0025"/>
			<joint name="leaf1-joint" type="free" damping="0" armature="0"/>
			<geom name="leaf1-geo" type="mesh" mesh="prop_ccw" pos="0.1 -0.1 0.025" quat="1.0 0.0 0.0 0." mass=".0025"/>
			<joint name="leaf2-joint" type="free" damping="0" armature="0"/>
			<geom name="leaf2-geo" type="mesh" mesh="prop_ccw" pos="-0.1 -0.1 0.025" quat="1.0 0.0 0.0 0." mass=".0025"/>
			<joint name="leaf3-joint" type="free" damping="0" armature="0"/>
			<geom name="leaf3-geo" type="mesh" mesh="prop_ccw" pos="-0.1 0.1 0.025" quat="1.0 0.0 0.0 0." mass=".0025"/>
		</body> -->
	</worldbody>
    <actuator>
			<!-- 0.73575 -->
			<motor ctrllimited="true" ctrlrange="0.0 1.0" gear="-0.1" joint="leaf0-joint"/>
			<motor ctrllimited="true" ctrlrange="0.0 1.0" gear="0.1" joint="leaf1-joint"/>
			<motor ctrllimited="true" ctrlrange="0.0 1.0" gear="-0.1" joint="leaf2-joint"/>
			<motor ctrllimited="true" ctrlrange="0.0 1.0" gear="0.1" joint="leaf3-joint"/>
			<motor ctrllimited="true" ctrlrange="0.0 5.0" gear=".0  0. 1 0. 0. 0." site="motor0"/>
      <motor ctrllimited="true" ctrlrange="0.0 5.0" gear=".0  0. 1 0. 0. 0." site="motor1"/>
      <motor ctrllimited="true" ctrlrange="0.0 5.0" gear=".0  0. 1 0. 0. 0." site="motor2"/>
      <motor ctrllimited="true" ctrlrange="0.0 5.0" gear=".0  0. 1 0. 0. 0." site="motor3"/>
	</actuator>
</mujoco>
